2025-10-14 16:19:35,006 INFO     Running plot_data.py
2025-10-14 16:19:35,147 ERROR    Gusto is logging this unhandled exception:
Traceback (most recent call last):
  File "/home/katie795/NeuralPDE_workspace/NeuralPDE/src/plot_data.py", line 38, in <module>
    dataset = load_hdf5_dataset(args.data)
              ^^^^^^^^^^^^^^^^^^^^^^^^^^^^
  File "/home/katie795/NeuralPDE_workspace/NeuralPDE/src/neural_pde/datasets.py", line 37, in load_hdf5_dataset
    t_final = f["base/t_final"]
              ~^^^^^^^^^^^^^^^^
  File "h5py/_objects.pyx", line 56, in h5py._objects.with_phil.wrapper
  File "h5py/_objects.pyx", line 57, in h5py._objects.with_phil.wrapper
  File "/home/katie795/software/venv-firedrake/lib/python3.12/site-packages/h5py/_hl/group.py", line 360, in __getitem__
    oid = h5o.open(self.id, self._e(name), lapl=self._lapl)
          ^^^^^^^^^^^^^^^^^^^^^^^^^^^^^^^^^^^^^^^^^^^^^^^^^
  File "h5py/_objects.pyx", line 56, in h5py._objects.with_phil.wrapper
  File "h5py/_objects.pyx", line 57, in h5py._objects.with_phil.wrapper
  File "h5py/h5o.pyx", line 257, in h5py.h5o.open
KeyError: "Unable to open object (object 't_final' doesn't exist)"
