2025-10-23 10:54:11,824 INFO     Running data_generator_swes.py --filename data/data_train_swes_vorticity_nref_5_0.05.h5 --nref 5 --omega 1e-4 --g 9.8 --nt 10 --tfinalmax 0.05 --nsamples 8 --t_interval 10 --t_sigma 5 --t_lowest 0 --t_highest 10
2025-10-23 10:54:13,968 ERROR    Gusto is logging this unhandled exception:
Traceback (most recent call last):
  File "/home/katie795/NeuralPDE_workspace/NeuralPDE/src/data_generator_swes.py", line 148, in <module>
    dataset.prepare_for_model()
  File "/home/katie795/NeuralPDE_workspace/NeuralPDE/src/neural_pde/datasets.py", line 521, in prepare_for_model
    vort1 = netCDF4file.load_function(mesh_h5, 'RelativeVorticity', idx=end)
            ^^^^^^^^^^^^^^^^^^^^^^^^^
  File "src/netCDF4/_netCDF4.pyx", line 3182, in netCDF4._netCDF4.Dataset.__getattr__
  File "src/netCDF4/_netCDF4.pyx", line 3127, in netCDF4._netCDF4.Dataset.getncattr
  File "src/netCDF4/_netCDF4.pyx", line 1667, in netCDF4._netCDF4._get_att
  File "src/netCDF4/_netCDF4.pyx", line 2164, in netCDF4._netCDF4._ensure_nc_success
AttributeError: NetCDF: Attribute not found
