2025-10-23 10:39:08,076 INFO     Running data_generator_swes.py --filename data/data_test_swes_nref_5_0.01.h5 --nref 5 --omega 1e-4 --g 9.8 --nt 100 --tfinalmax 0.01 --nsamples 128 --t_interval 50 --t_sigma 25 --t_lowest 800 --t_highest 100
2025-10-23 10:39:09,931 ERROR    Gusto is logging this unhandled exception:
Traceback (most recent call last):
  File "/home/katie795/NeuralPDE_workspace/NeuralPDE/src/data_generator_swes.py", line 148, in <module>
    dataset.prepare_for_model()
  File "/home/katie795/NeuralPDE_workspace/NeuralPDE/src/neural_pde/datasets.py", line 506, in prepare_for_model
    start = np.random.randint(self.t_lowest, highest)
            ^^^^^^^^^^^^^^^^^^^^^^^^^^^^^^^^^^^^^^^^^
  File "numpy/random/mtrand.pyx", line 796, in numpy.random.mtrand.RandomState.randint
  File "numpy/random/_bounded_integers.pyx", line 1334, in numpy.random._bounded_integers._rand_int64
ValueError: low >= high
