2025-10-14 15:14:26,233 INFO     Running data_generator_swes.py
2025-10-14 15:14:29,115 ERROR    Gusto is logging this unhandled exception:
Traceback (most recent call last):
  File "/home/katie795/NeuralPDE_workspace/NeuralPDE/src/data_generator_swes.py", line 98, in <module>
    dataset.prepare_for_model()
  File "/home/katie795/NeuralPDE_workspace/NeuralPDE/src/neural_pde/datasets.py", line 468, in prepare_for_model
    p.apply(w2, u_tar)    # target u data
    ^^^^^^^^^^^^^^^^^^
  File "/home/katie795/NeuralPDE_workspace/NeuralPDE/src/neural_pde/datasets.py", line 308, in apply
    self._lvs[j].solve()
  File "petsc4py/PETSc/Log.pyx", line 250, in petsc4py.PETSc.Log.EventDecorator.decorator.wrapped_func
  File "petsc4py/PETSc/Log.pyx", line 251, in petsc4py.PETSc.Log.EventDecorator.decorator.wrapped_func
  File "/home/katie795/software/venv-firedrake/lib/python3.12/site-packages/firedrake/adjoint_utils/variational_solver.py", line 108, in wrapper
    out = solve(self, **kwargs)
          ^^^^^^^^^^^^^^^^^^^^^
  File "/home/katie795/software/venv-firedrake/lib/python3.12/site-packages/firedrake/variational_solver.py", line 356, in solve
    self.snes.solve(None, work)
KeyboardInterrupt
