2025-10-15 11:44:25,554 INFO     Running plot_data.py --move_to_windows
2025-10-15 11:44:26,522 ERROR    Gusto is logging this unhandled exception:
Traceback (most recent call last):
  File "/home/katie795/NeuralPDE_workspace/NeuralPDE/src/plot_data.py", line 104, in <module>
    move_files_and_directories(wsl_folder1, windows_folder)
  File "/home/katie795/NeuralPDE_workspace/NeuralPDE/src/plot_data.py", line 95, in move_files_and_directories
    shutil.move(wsl_path, windows_path)
  File "/usr/lib/python3.12/shutil.py", line 884, in move
    raise Error("Destination path '%s' already exists" % real_dst)
shutil.Error: Destination path '/mnt/c/Users/kathe/OneDrive/Desktop/paraview_data/output_0011/output_0011' already exists
