2025-10-17 11:01:40,192 INFO     Running data_generator_swes.py --filename data/data_test_swes_nref_3_0.0001.h5 --nref 3 --omega 7.292e-5 --g 9.8 --nt 5 --tfinalmax 0.0001 --nsamples 16 --t_interval 2 --t_sigma 1
2025-10-17 11:01:40,198 ERROR    Gusto is logging this unhandled exception:
Traceback (most recent call last):
  File "/home/katie795/NeuralPDE_workspace/NeuralPDE/src/data_generator_swes.py", line 8, in <module>
    from neural_pde.datasets import ShallowWaterEquationsDataset
  File "/home/katie795/NeuralPDE_workspace/NeuralPDE/src/neural_pde/datasets.py", line 11, in <module>
    from gusto import (
  File "/home/katie795/software/gusto/gusto/gusto/__init__.py", line 12, in <module>
    from gusto.rexi import *                             # noqa
    ^^^^^^^^^^^^^^^^^^^^^^^^
  File "/home/katie795/software/gusto/gusto/gusto/rexi/__init__.py", line 1, in <module>
    from gusto.rexi.rexi import *                     # noqa
    ^^^^^^^^^^^^^^^^^^^^^^^^^^^^^
  File "<frozen importlib._bootstrap>", line 1360, in _find_and_load
  File "<frozen importlib._bootstrap>", line 1331, in _find_and_load_unlocked
  File "<frozen importlib._bootstrap>", line 935, in _load_unlocked
  File "<frozen importlib._bootstrap_external>", line 991, in exec_module
  File "<frozen importlib._bootstrap_external>", line 1087, in get_code
  File "<frozen importlib._bootstrap_external>", line 1187, in get_data
KeyboardInterrupt
