2025-10-17 11:25:52,928 INFO     Running train.py
2025-10-17 11:25:52,976 ERROR    Gusto is logging this unhandled exception:
Traceback (most recent call last):
  File "/home/katie795/NeuralPDE_workspace/NeuralPDE/src/train.py", line 60, in <module>
    train_ds = load_hdf5_dataset(config["data"]["train"])
               ^^^^^^^^^^^^^^^^^^^^^^^^^^^^^^^^^^^^^^^^^^
  File "/home/katie795/NeuralPDE_workspace/NeuralPDE/src/neural_pde/datasets.py", line 38, in load_hdf5_dataset
    t_initial = f["base/t_initial"]
                ~^^^^^^^^^^^^^^^^^^
  File "h5py/_objects.pyx", line 56, in h5py._objects.with_phil.wrapper
  File "h5py/_objects.pyx", line 57, in h5py._objects.with_phil.wrapper
  File "/home/katie795/software/venv-firedrake/lib/python3.12/site-packages/h5py/_hl/group.py", line 360, in __getitem__
    oid = h5o.open(self.id, self._e(name), lapl=self._lapl)
          ^^^^^^^^^^^^^^^^^^^^^^^^^^^^^^^^^^^^^^^^^^^^^^^^^
  File "h5py/_objects.pyx", line 56, in h5py._objects.with_phil.wrapper
  File "h5py/_objects.pyx", line 57, in h5py._objects.with_phil.wrapper
  File "h5py/h5o.pyx", line 257, in h5py.h5o.open
KeyError: "Unable to open object (object 't_initial' doesn't exist)"
