2025-10-22 15:15:10,802 INFO     Running data_generator_swes.py --filename data/data_train_swes_nref_3_10.h5 --nref 3 --omega 1e-4 --g 9.8 --nt 1000 --tfinalmax 10 --nsamples 4096 --t_interval 50 --t_sigma 25 --t_lowest 0 --t_highest 800
2025-10-22 15:17:48,708 ERROR    Gusto is logging this unhandled exception:
Traceback (most recent call last):
  File "/home/katie795/NeuralPDE_workspace/NeuralPDE/src/data_generator_swes.py", line 148, in <module>
    dataset.prepare_for_model()
  File "/home/katie795/NeuralPDE_workspace/NeuralPDE/src/neural_pde/datasets.py", line 523, in prepare_for_model
    p2.apply(h1, h_inp)
  File "/home/katie795/NeuralPDE_workspace/NeuralPDE/src/neural_pde/datasets.py", line 326, in apply
    lvs = self.create_linear_solver()
          ^^^^^^^^^^^^^^^^^^^^^^^^^^^
  File "/home/katie795/NeuralPDE_workspace/NeuralPDE/src/neural_pde/datasets.py", line 314, in create_linear_solver
    lvs = LinearVariationalSolver(lvp)
          ^^^^^^^^^^^^^^^^^^^^^^^^^^^^
  File "petsc4py/PETSc/Log.pyx", line 250, in petsc4py.PETSc.Log.EventDecorator.decorator.wrapped_func
  File "petsc4py/PETSc/Log.pyx", line 251, in petsc4py.PETSc.Log.EventDecorator.decorator.wrapped_func
  File "/usr/lib/python3.12/contextlib.py", line 81, in inner
    return func(*args, **kwds)
           ^^^^^^^^^^^^^^^^^^^
  File "/home/katie795/software/venv-firedrake/lib/python3.12/site-packages/firedrake/adjoint_utils/variational_solver.py", line 47, in wrapper
    init(self, problem, *args, **kwargs)
  File "/home/katie795/software/venv-firedrake/lib/python3.12/site-packages/firedrake/variational_solver.py", line 276, in __init__
    ctx.set_function(self.snes)
  File "/home/katie795/software/venv-firedrake/lib/python3.12/site-packages/firedrake/solving_utils.py", line 305, in set_function
    with self._F.dat.vec_wo as v:
KeyboardInterrupt
