2025-10-20 14:14:47,399 INFO     Running data_generator_swes.py --filename data/data_valid_swes_nref_4_1.h5 --nref 4 --omega 7.292e-5 --g 9.8 --nt 100000 --tfinalmax 1 --nsamples 128 --t_interval 50 --t_sigma 25
2025-10-20 14:14:47,940 ERROR    Gusto is logging this unhandled exception:
Traceback (most recent call last):
  File "/home/katie795/NeuralPDE_workspace/NeuralPDE/src/data_generator_swes.py", line 129, in <module>
    dataset.prepare_for_model()
  File "/home/katie795/NeuralPDE_workspace/NeuralPDE/src/neural_pde/datasets.py", line 494, in prepare_for_model
    w1 = afile.load_function(mesh_h5, "u", idx=start)
         ^^^^^^^^^^^^^^^^^^^^^^^^^^^^^^^^^^^^^^^^^^^^
  File "petsc4py/PETSc/Log.pyx", line 250, in petsc4py.PETSc.Log.EventDecorator.decorator.wrapped_func
  File "petsc4py/PETSc/Log.pyx", line 251, in petsc4py.PETSc.Log.EventDecorator.decorator.wrapped_func
  File "/home/katie795/software/venv-firedrake/lib/python3.12/site-packages/firedrake/checkpointing.py", line 1351, in load_function
    raise RuntimeError(f"""
RuntimeError: 
                Function (u) not found under either of the following path in results/output/chkpt.h5:

                topologies/firedrake_mixed_meshes/IcosahedralMesh
                topologies/IcosahedralMesh_topology/firedrake_meshes/IcosahedralMesh
            
