2025-10-23 13:47:00,399 INFO     Running data_generator_swes.py --filename data/data_train_swes_nref_5_0.01.h5 --nref 5 --omega 1e-4 --g 9.8 --nt 100 --tfinalmax 0.01 --nsamples 1 --t_interval 10 --t_sigma 5 --t_lowest 0 --t_highest 10
2025-10-23 13:47:02,140 ERROR    Gusto is logging this unhandled exception:
Traceback (most recent call last):
  File "/home/katie795/NeuralPDE_workspace/NeuralPDE/src/data_generator_swes.py", line 148, in <module>
    dataset.prepare_for_model()
  File "/home/katie795/NeuralPDE_workspace/NeuralPDE/src/neural_pde/datasets.py", line 497, in prepare_for_model
    diagnostics = dg.Diagnostics(V_BDM, V_CG)
                  ^^^^^^^^^^^^^^^^^^^^^^^^^^^
  File "/home/katie795/NeuralPDE_workspace/NeuralPDE/src/diagnostics.py", line 30, in __init__
    b_vorticity = phi * inner(n, rot(self._u)) * dx
                  ~~~~~~~~~~~~~~~~~~~~~~~~~~~~~^~~~
  File "/home/katie795/software/venv-firedrake/lib/python3.12/site-packages/ufl/measure.py", line 427, in __rmul__
    raise ValueError(
ValueError: Multiple domains found, making the choice of integration domain ambiguous.
