2025-10-23 14:41:37,358 INFO     Running data_generator_swes.py --filename data/data_train_swes_nref_5_0.01.h5 --nref 5 --omega 1e-4 --g 9.8 --nt 100 --tfinalmax 0.01 --nsamples 1 --t_interval 10 --t_sigma 5 --t_lowest 0 --t_highest 10
2025-10-23 14:41:52,771 ERROR    Gusto is logging this unhandled exception:
Traceback (most recent call last):
  File "/home/katie795/NeuralPDE_workspace/NeuralPDE/src/data_generator_swes.py", line 148, in <module>
    dataset.prepare_for_model()
  File "/home/katie795/NeuralPDE_workspace/NeuralPDE/src/neural_pde/datasets.py", line 504, in prepare_for_model
    p1.apply(u, u_func)    # input u data
    ^^^^^^^^^^^^^^^^^^^
  File "/home/katie795/NeuralPDE_workspace/NeuralPDE/src/neural_pde/datasets.py", line 333, in apply
    lvs[j].solve()
  File "petsc4py/PETSc/Log.pyx", line 250, in petsc4py.PETSc.Log.EventDecorator.decorator.wrapped_func
  File "petsc4py/PETSc/Log.pyx", line 251, in petsc4py.PETSc.Log.EventDecorator.decorator.wrapped_func
  File "/home/katie795/software/venv-firedrake/lib/python3.12/site-packages/firedrake/adjoint_utils/variational_solver.py", line 108, in wrapper
    out = solve(self, **kwargs)
          ^^^^^^^^^^^^^^^^^^^^^
  File "/home/katie795/software/venv-firedrake/lib/python3.12/site-packages/firedrake/variational_solver.py", line 356, in solve
    self.snes.solve(None, work)
KeyboardInterrupt
