2025-10-14 15:20:22,143 INFO     Running data_generator_swes.py
2025-10-14 15:20:22,742 ERROR    Gusto is logging this unhandled exception:
Traceback (most recent call last):
  File "/home/katie795/NeuralPDE_workspace/NeuralPDE/src/data_generator_swes.py", line 98, in <module>
    dataset.prepare_for_model()
  File "/home/katie795/NeuralPDE_workspace/NeuralPDE/src/neural_pde/datasets.py", line 459, in prepare_for_model
    p = Projector(V_BDM, V_CG)
        ^^^^^^^^^^^^^^^^^^^^^^
  File "/home/katie795/NeuralPDE_workspace/NeuralPDE/src/neural_pde/datasets.py", line 298, in __init__
    b_hscalar = phi * self._w_hdiv * dx
                ~~~~~~~~~~~~~~~~~~~^~~~
  File "/home/katie795/software/venv-firedrake/lib/python3.12/site-packages/ufl/measure.py", line 385, in __rmul__
    raise ValueError(
ValueError: Can only integrate scalar expressions. The integrand is a tensor expression with value shape (3,) and free indices with labels ().
