2025-10-22 15:42:27,612 INFO     Running evaluate.py
2025-10-22 15:42:38,542 ERROR    Gusto is logging this unhandled exception:
Traceback (most recent call last):
  File "petsc4py/PETSc/petscsnes.pxi", line 352, in petsc4py.PETSc.SNES_Function
  File "/home/katie795/software/venv-firedrake/lib/python3.12/site-packages/firedrake/solving_utils.py", line 433, in form_function
    ctx._assemble_residual(tensor=ctx._F, current_state=ctx._x)
  File "/home/katie795/software/venv-firedrake/lib/python3.12/site-packages/firedrake/assemble.py", line 1005, in assemble
    self.execute_parloops(tensor)
  File "/home/katie795/software/venv-firedrake/lib/python3.12/site-packages/firedrake/assemble.py", line 1249, in execute_parloops
    parloop()
  File "petsc4py/PETSc/Log.pyx", line 250, in petsc4py.PETSc.Log.EventDecorator.decorator.wrapped_func
  File "petsc4py/PETSc/Log.pyx", line 251, in petsc4py.PETSc.Log.EventDecorator.decorator.wrapped_func
  File "/home/katie795/software/venv-firedrake/lib/python3.12/site-packages/pyop2/parloop.py", line 252, in __call__
    self.global_to_local_end()
  File "/home/katie795/software/venv-firedrake/lib/python3.12/site-packages/pyop2/parloop.py", line 328, in global_to_local_end
    op(self.arguments[idx].data)
KeyboardInterrupt

The above exception was the direct cause of the following exception:

Traceback (most recent call last):
  File "/home/katie795/NeuralPDE_workspace/NeuralPDE/src/evaluate.py", line 145, in <module>
    f_pred_dg.assign(time_integration(X, V, V_DG, t, dt, dataset.metadata["omega"]))
                     ^^^^^^^^^^^^^^^^^^^^^^^^^^^^^^^^^^^^^^^^^^^^^^^^^^^^^^^^^^^^^^
  File "/home/katie795/NeuralPDE_workspace/NeuralPDE/src/evaluate.py", line 56, in time_integration
    lvs.solve()
  File "petsc4py/PETSc/Log.pyx", line 250, in petsc4py.PETSc.Log.EventDecorator.decorator.wrapped_func
  File "petsc4py/PETSc/Log.pyx", line 251, in petsc4py.PETSc.Log.EventDecorator.decorator.wrapped_func
  File "/home/katie795/software/venv-firedrake/lib/python3.12/site-packages/firedrake/adjoint_utils/variational_solver.py", line 108, in wrapper
    out = solve(self, **kwargs)
          ^^^^^^^^^^^^^^^^^^^^^
  File "/home/katie795/software/venv-firedrake/lib/python3.12/site-packages/firedrake/variational_solver.py", line 356, in solve
    self.snes.solve(None, work)
  File "petsc4py/PETSc/SNES.pyx", line 1738, in petsc4py.PETSc.SNES.solve
petsc4py.PETSc.Error: error code 101
[0] SNESSolve() at /home/katie795/software/petsc/src/snes/interface/snes.c:4846
[0] SNESSolve_KSPONLY() at /home/katie795/software/petsc/src/snes/impls/ksponly/ksponly.c:27
[0] SNESComputeFunction() at /home/katie795/software/petsc/src/snes/interface/snes.c:2476
