2025-10-14 15:34:43,833 INFO     Running data_generator_swes.py
2025-10-14 15:34:44,520 ERROR    Gusto is logging this unhandled exception:
Traceback (most recent call last):
  File "/home/katie795/NeuralPDE_workspace/NeuralPDE/src/data_generator_swes.py", line 98, in <module>
    dataset.prepare_for_model()
  File "/home/katie795/NeuralPDE_workspace/NeuralPDE/src/neural_pde/datasets.py", line 498, in prepare_for_model
    p2.apply(h1, h_inp)
  File "/home/katie795/NeuralPDE_workspace/NeuralPDE/src/neural_pde/datasets.py", line 329, in apply
    lvs = self.create_linear_solver()
          ^^^^^^^^^^^^^^^^^^^^^^^^^^^
  File "/home/katie795/NeuralPDE_workspace/NeuralPDE/src/neural_pde/datasets.py", line 321, in create_linear_solver
    return lvs
           ^^^
UnboundLocalError: cannot access local variable 'lvs' where it is not associated with a value
