2025-10-13 13:08:12,715 INFO     Running data_generator_swes.py
2025-10-13 13:08:13,214 INFO     Semi-implicit Quasi-Newton: Using solver prognostics ['u', 'D']
2025-10-13 13:08:13,455 INFO     Physical parameters that take non-default values:
2025-10-13 13:08:13,455 INFO     
2025-10-13 13:08:13,641 DEBUG    Dumping output to disk
2025-10-13 13:08:13,642 ERROR    Gusto is logging this unhandled exception:
Traceback (most recent call last):
  File "/home/katie795/NeuralPDE_workspace/NeuralPDE/src/data_generator_swes.py", line 82, in <module>
    dataset.generate_full_dataset()
  File "/home/katie795/NeuralPDE_workspace/NeuralPDE/src/neural_pde/datasets.py", line 423, in generate_full_dataset
    stepper.run(t=0, tmax=self.t_final_max)
  File "/home/katie795/software/gusto/gusto/gusto/timestepping/semi_implicit_quasi_newton.py", line 599, in run
    super().run(t, tmax, pick_up=pick_up)
  File "/home/katie795/software/gusto/gusto/gusto/timestepping/timestepper.py", line 219, in run
    self.io.setup_dump(self.fields, t, pick_up)
  File "/home/katie795/software/gusto/gusto/gusto/core/io.py", line 418, in setup_dump
    raise GustoIOError(f'results directory {self.dumpdir} already exists')
gusto.core.io.GustoIOError: results directory results/output already exists
