2025-10-21 12:06:12,329 INFO     Running evaluate.py
2025-10-21 12:06:20,381 ERROR    Gusto is logging this unhandled exception:
Traceback (most recent call last):
  File "/home/katie795/NeuralPDE_workspace/NeuralPDE/src/evaluate.py", line 125, in <module>
    t_final = float(dataset.metadata["t_final_max"])
                    ~~~~~~~~~~~~~~~~^^^^^^^^^^^^^^^
KeyError: 't_final_max'
