2025-10-21 12:08:26,790 INFO     Running evaluate.py
2025-10-21 12:08:34,649 ERROR    Gusto is logging this unhandled exception:
Traceback (most recent call last):
  File "/home/katie795/NeuralPDE_workspace/NeuralPDE/src/evaluate.py", line 142, in <module>
    f_pred_dg.assign(time_integration(X, V, V_DG, t, dt, dataset.metadata["omega"]))
                                                         ~~~~~~~~~~~~~~~~^^^^^^^^^
KeyError: 'omega'
