2025-10-20 10:10:05,720 INFO     Running data_generator_swes.py --filename data/data_valid_swes_nref_4_1.h5 --nref 4 --omega 7.292e-5 --g 9.8 --nt 1000 --tfinalmax 1 --nsamples 128 --t_interval 50 --t_sigma 25
2025-10-20 10:10:06,409 ERROR    Gusto is logging this unhandled exception:
Traceback (most recent call last):
  File "/home/katie795/NeuralPDE_workspace/NeuralPDE/src/data_generator_swes.py", line 129, in <module>
    dataset.prepare_for_model()
  File "/home/katie795/NeuralPDE_workspace/NeuralPDE/src/neural_pde/datasets.py", line 465, in prepare_for_model
    with CheckpointFile("results/output/chkpt.h5", 'r') as afile:
  File "/home/katie795/software/venv-firedrake/lib/python3.12/site-packages/firedrake/checkpointing.py", line 558, in __exit__
    self.close()
  File "/home/katie795/software/venv-firedrake/lib/python3.12/site-packages/firedrake/checkpointing.py", line 1727, in close
    self.viewer.destroy()
  File "petsc4py/PETSc/Viewer.pyx", line 176, in petsc4py.PETSc.Viewer.destroy
petsc4py.PETSc.Error: error code 76
[0] PetscViewerDestroy() at /home/katie795/software/petsc/src/sys/classes/viewer/interface/view.c:101
[0] PetscViewerDestroy_HDF5() at /home/katie795/software/petsc/src/sys/classes/viewer/impls/hdf5/hdf5v.c:126
[0] PetscViewerFileClose_HDF5() at /home/katie795/software/petsc/src/sys/classes/viewer/impls/hdf5/hdf5v.c:107
[0] Error in external library
[0] Error in HDF5 call H5Fclose() Status -1
